2022-11-07 10:28:29 WARNING Retrying (Retry(total=2, connect=None, read=None, redirect=None, status=None)) after connection broken by 'NewConnectionError('<urllib3.connection.HTTPSConnection object at 0x0000028239B22C10>: Failed to establish a new connection: [Errno 11002] getaddrinfo failed')': /api/5288891/store/
2022-11-07 10:28:29 WARNING Retrying (Retry(total=1, connect=None, read=None, redirect=None, status=None)) after connection broken by 'NewConnectionError('<urllib3.connection.HTTPSConnection object at 0x0000028239B22D60>: Failed to establish a new connection: [Errno 11002] getaddrinfo failed')': /api/5288891/store/
2022-11-07 10:28:29 WARNING Retrying (Retry(total=0, connect=None, read=None, redirect=None, status=None)) after connection broken by 'NewConnectionError('<urllib3.connection.HTTPSConnection object at 0x0000028239B22EB0>: Failed to establish a new connection: [Errno 11002] getaddrinfo failed')': /api/5288891/store/
2022-11-07 10:39:45 ERROR 403 response executing GraphQL.
2022-11-07 10:39:45 ERROR 
<html><head>
<meta http-equiv="content-type" content="text/html;charset=utf-8">
<title>403 Forbidden</title>
</head>
<body text=#000000 bgcolor=#ffffff>
<h1>Error: Forbidden</h1>
<h2>Your client does not have permission to get URL <code>/graphql</code> from this server.</h2>
<h2></h2>
</body></html>

2022-11-07 10:41:13 WARNING Retrying (Retry(total=2, connect=None, read=None, redirect=None, status=None)) after connection broken by 'NewConnectionError('<urllib3.connection.HTTPSConnection object at 0x0000024B39DC35B0>: Failed to establish a new connection: [Errno 11002] getaddrinfo failed')': /api/5288891/store/
2022-11-07 10:41:13 WARNING Retrying (Retry(total=1, connect=None, read=None, redirect=None, status=None)) after connection broken by 'NewConnectionError('<urllib3.connection.HTTPSConnection object at 0x0000024B39DC3700>: Failed to establish a new connection: [Errno 11002] getaddrinfo failed')': /api/5288891/store/
2022-11-07 10:41:13 WARNING Retrying (Retry(total=0, connect=None, read=None, redirect=None, status=None)) after connection broken by 'NewConnectionError('<urllib3.connection.HTTPSConnection object at 0x0000024B39DC3850>: Failed to establish a new connection: [Errno 11002] getaddrinfo failed')': /api/5288891/store/
2022-11-07 10:44:28 ERROR Received None when attempting to get digest for wandb/local
